Workbook
Name _TAR1: 'Misselaneos '!$P$3
Name _TAR2: 'Misselaneos '!$P$4

Sheet Balance
B1: Parametros | E1: Balance | F1: 45926 | G1: =F1+7 -> 45933 | H1: =G1+7 -> 45940 | I1: =H1+7 -> 45947 | J1: =I1+7 -> 45954 | K1: =J1+7 -> 45961 | L1: =K1+7 -> 45968 | M1: =L1+7 -> 45975 | N1: =M1+7 -> 45982 | ... BJ1: =BI1+7 -> 46318
C2: Ahorros | G2: 5000 | H2: 5000 | I2: 5000 | J2: 7000 | K2: 7000 | L2: 7000 | M2: 7000 | N2: 7000 | O2: 7000 | P2: 7000 | Q2: 7000 | R2: 7000 | S2: 7000 | T2: 7000 | U2: 7000 | V2: 7000 | W2: 7000 | X2: 7000 | Y2: 7000 | Z2: 7000 | AA2: 7000 | AB2: 7000 | AC2: 7000 | AD2: 7000 | AE2: 7000 | AF2: 7000 | AG2: 7000 | AH2: 7000 | AI2: 7000 | AJ2: 7000 | AK2: 7000 | AL2: 7000 | AM2: 7000 | AN2: 7000 | AO2: 7000 | AP2: 7000 | AQ2: 7000 | AR2: 7000 | AS2: 7000 | AT2: 7000 | AU2: 7000 | AV2: 7000 | AW2: 7000 | AX2: 7000 | AY2: 7000 | AZ2: 7000 | BA2: 7000 | BB2: 7000 | BC2: 7000 | BD2: 7000 | BE2: 7000 | BF2: 7000 | BG2: 7000 | BH2: 7000 | BI2: 7000 | BJ2: 7000
D3: Deposito Extra | G3: 3700 | S3: =(20000*3)*50% -> 30000 | AA3: 30000 | AC3: 30000 | AE3: 30000 | AG3: 30000 | AI3: 30000 | AK3: 30000 | AM3: 30000 | AO3: 30000 | AQ3: 30000 | AS3: 30000 | AU3: 30000 | AW3: 30000 | AY3: 30000 | BA3: 30000 | BC3: 30000 | BE3: 30000 | BG3: 30000 | BI3: 30000
D4: Balance | F4: 375262.6 | G4: =F4+G2+G3 -> 383962.6 | H4: =G4+H2 -> 388962.6 | I4: =H4+I2-I13-H7+I3-H10 -> 4353.76 | J4: =I4+J2+J3 -> 11353.76 | K4: =J4+K2+K3 -> 18353.76 | L4: =K4+L2-K10+L3 -> 25353.76 | M4: =L4+M2+M3 -> 32353.76 | N4: =M4+N2+N3 -> 39353.76 | O4: =N4+O2+O3 -> 46353.76 | P4: =O4+P2+P3 -> 53353.76 | Q4: =P4+Q2+Q3 -> 60353.76 | R4: =Q4+R2+R3 -> 67353.76 | S4: =R4+S2+S3 -> 104353.76 | T4: =S4+T2+T3 -> 111353.76 | ... Z4: =Y4+Z2+Z3 -> 153353.76 | AA4: =Z4+AA2+AA3-AA12 -> 40353.76 | AB4: =AA4+AB2+AB3 -> 47353.76 | AC4: =AB4+AC2+AC3-AC12 -> -65647.24 | AD4: =AC4+AD2+AD3 -> -58647.24 | AE4: =AD4+AE2+AE3-AE12 -> -171649.24 | AF4: =AE4+AF2+AF3 -> -164649.24 | AG4: =AF4+AG2+AG3-AG12 -> -277652.24 | AH4: =AG4+AH2+AH3 -> -270652.24 | AI4: =AH4+AI2+AI3-AI12 -> -383656.24 | AJ4: =AI4+AJ2+AJ3 -> -376656.24 | AK4: =AJ4+AK2+AK3-AK12 -> -489661.24 | AL4: =AK4+AL2+AL3 -> -482661.24 | AM4: =AL4+AM2+AM3-AM12 -> -595667.24 | AN4: =AM4+AN2+AN3 -> -588667.24 | AO4: =AN4+AO2+AO3-AO12 -> -701674.24 | AP4: =AO4+AP2+AP3 -> -694674.24 | AQ4: =AP4+AQ2+AQ3-AQ12 -> -807682.24 | AR4: =AQ4+AR2+AR3 -> -800682.24 | AS4: =AR4+AS2+AS3-AS12 -> -913691.24 | AT4: =AS4+AT2+AT3 -> -906691.24 | AU4: =AT4+AU2+AU3-AU12 -> -1019701.2 | AV4: =AU4+AV2+AV3 -> -1012701.2 | AW4: =AV4+AW2+AW3-AW12 -> -1125712.2 | AX4: =AW4+AX2+AX3 -> -1118712.2 | AY4: =AX4+AY2+AY3-AY12 -> -1231724.2 | AZ4: =AY4+AZ2+AZ3 -> -1224724.2 | BA4: =AZ4+BA2+BA3-BA12 -> -1337737.2 | BB4: =BA4+BB2+BB3 -> -1330737.2 | BC4: =BB4+BC2+BC3-BC12 -> -1443751.2 | BD4: =BC4+BD2+BD3 -> -1436751.2 | BE4: =BD4+BE2+BE3-BE12 -> -1549766.2 | BF4: =BE4+BF2+BF3 -> -1542766.2 | BG4: =BF4+BG2+BG3-BG12 -> -1655782.2 | BH4: =BG4+BH2+BH3 -> -1648782.2 | BI4: =BH4+BI2+BI3-BI12 -> -1761799.2 | BJ4: =BI4+BJ2+BJ3 -> -1754799.2
C6: Prestamos | G6: 1647.34 | H6: 1647.34
D7: Balance | F7: 233361.67 | G7: =F7-G6 -> 231714.33 | H7: =G7-H6 -> 230066.99
C9: Resort | G9: 144.27 | H9: 144.27
D10: Balance | F10: 9830.39 | G10: =F10-G9 -> 9686.12 | H10: =G10-H9 -> 9541.85
C12: Certificado | I12: 150000 | AA12: 150000 | AC12: 150001 | AE12: 150002 | AG12: 150003 | AI12: 150004 | AK12: 150005 | AM12: 150006 | AO12: 150007 | AQ12: 150008 | AS12: 150009 | AU12: 150010 | AW12: 150011 | AY12: 150012 | BA12: 150013 | BC12: 150014 | BE12: 150015 | BG12: 150016 | BI12: 150017
D13: =0.06/52 -> 0.0011538462 | I13: =I12 -> 150000 | J13: =(I13*$D$13)+I13+J12 -> 150173.08 | K13: =(J13*$D$13)+J13+K12 -> 150346.35 | L13: =(K13*$D$13)+K13+L12 -> 150519.83 | M13: =(L13*$D$13)+L13+M12 -> 150693.51 | N13: =(M13*$D$13)+M13+N12 -> 150867.38 | O13: =(N13*$D$13)+N13+O12 -> 151041.46 | P13: =(O13*$D$13)+O13+P12 -> 151215.74 | Q13: =(P13*$D$13)+P13+Q12 -> 151390.22 | ... BJ13: =(BI13*$D$13)+BI13+BJ12 -> 2916436.5
D14: =0.08/52 -> 0.0015384615
A16: 1 | C16: Ingresos
D17: Wacoal | F17: 7000 | G17: 7000 | H17: 7000 | I17: 7000 | J17: 7000 | K17: 7000 | L17: 7000 | M17: 7000 | N17: 7000 | O17: 7000 | P17: 7000 | Q17: 7000 | R17: 7000 | S17: 7000 | T17: 7000 | U17: 7000 | X17: 7000 | Y17: 7000 | Z17: 7000 | AA17: 7000 | AB17: 7000 | AC17: 7000 | AD17: 7000 | AE17: 7000 | AF17: 7000 | AG17: 7000 | AH17: 7000 | AI17: 7000 | AJ17: 7000 | AK17: 7000 | AL17: 7000 | AM17: 7000 | AN17: 7000 | AO17: 7000 | AP17: 7000 | AQ17: 7000 | AR17: 7000 | AS17: 7000 | AT17: 7000 | AU17: 7000 | AV17: 7000 | AW17: 7000 | AX17: 7000 | AY17: 7000 | AZ17: 7000 | BA17: 7000 | BB17: 7000 | BD17: 7000 | BE17: 7000 | BF17: 7000 | BG17: 7000 | BH17: 7000 | BI17: 7000 | BJ17: 7000
D18: Re-Embolso
D19: cuadre
D20: Otros
B22: Tarjeta de Credito
A23: =IF(D23>0,MAX($A$16:A22)+1,"") | C23: APAP | E23: =_TAR1 -> -1000 | G23: 2400 | J23: 2400 | N23: 2415 | S23: 2415 | W23: 2415
C24: Diferencia plan | F24: =IF(F23>0,SUM($F$23:F23)-SUM($F$25:F25),0) -> 0 | G24: =IF(G23>0,SUM($F$23:G23)-SUM($F$25:G25),0) -> 2400 | H24: =IF(H23>0,SUM($F$23:H23)-SUM($F$25:H25),0) -> 0 | I24: =IF(I23>0,SUM($F$23:I23)-SUM($F$25:I25),0) -> 0 | J24: =IF(J23>0,SUM($F$23:J23)-SUM($F$25:J25),0) -> 4800 | K24: =IF(K23>0,SUM($F$23:K23)-SUM($F$25:K25),0) -> 0 | L24: =IF(L23>0,SUM($F$23:L23)-SUM($F$25:L25),0) -> 0 | M24: =IF(M23>0,SUM($F$23:M23)-SUM($F$25:M25),0) -> 0 | ... BJ24: =IF(BJ23>0,SUM($F$23:BJ23)-SUM($F$25:BJ25),0) -> 0
A25: =IF(D25>0,MAX($A$16:A23)+1,"") | C25: Actual | F25: =SUMIFS('Misselaneos '!$D:$D,'Misselaneos '!$B:$B,Balance!F1,'Misselaneos '!$E:$E,$C$23) -> 0 | G25: =SUMIFS('Misselaneos '!$D:$D,'Misselaneos '!$B:$B,Balance!G1,'Misselaneos '!$E:$E,$C$23) -> 0 | H25: =SUMIFS('Misselaneos '!$D:$D,'Misselaneos '!$B:$B,Balance!H1,'Misselaneos '!$E:$E,$C$23) -> 0 | I25: =SUMIFS('Misselaneos '!$D:$D,'Misselaneos '!$B:$B,Balance!I1,'Misselaneos '!$E:$E,$C$23) -> 0 | J25: =SUMIFS('Misselaneos '!$D:$D,'Misselaneos '!$B:$B,Balance!J1,'Misselaneos '!$E:$E,$C$23) -> 0 | K25: =SUMIFS('Misselaneos '!$D:$D,'Misselaneos '!$B:$B,Balance!K1,'Misselaneos '!$E:$E,$C$23) -> 0 | L25: =SUMIFS('Misselaneos '!$D:$D,'Misselaneos '!$B:$B,Balance!L1,'Misselaneos '!$E:$E,$C$23) -> 0 | M25: . | N25: =SUMIFS('Misselaneos '!$D:$D,'Misselaneos '!$B:$B,Balance!N1,'Misselaneos '!$E:$E,$C$23) -> 0 | O25: =SUMIFS('Misselaneos '!$D:$D,'Misselaneos '!$B:$B,Balance!O1,'Misselaneos '!$E:$E,$C$23) -> 0 | P25: =SUMIFS('Misselaneos '!$D:$D,'Misselaneos '!$B:$B,Balance!P1,'Misselaneos '!$E:$E,$C$23) -> 0 | Q25: =SUMIFS('Misselaneos '!$D:$D,'Misselaneos '!$B:$B,Balance!Q1,'Misselaneos '!$E:$E,$C$23) -> 0 | R25: =SUMIFS('Misselaneos '!$D:$D,'Misselaneos '!$B:$B,Balance!R1,'Misselaneos '!$E:$E,$C$23) -> 0 | S25: =SUMIFS('Misselaneos '!$D:$D,'Misselaneos '!$B:$B,Balance!S1,'Misselaneos '!$E:$E,$C$23) -> 0 | T25: =SUMIFS('Misselaneos '!$D:$D,'Misselaneos '!$B:$B,Balance!T1,'Misselaneos '!$E:$E,$C$23) -> 0 | U25: =SUMIFS('Misselaneos '!$D:$D,'Misselaneos '!$B:$B,Balance!U1,'Misselaneos '!$E:$E,$C$23) -> 0 | ... BJ25: =SUMIFS('Misselaneos '!$D:$D,'Misselaneos '!$B:$B,Balance!BJ1,'Misselaneos '!$E:$E,$C$23) -> 0
A26: =IF(D26>0,MAX($A$16:A25)+1,"") -> 2 | D26: luz | F26: 1500 | K26: 1500 | O26: 1500 | S26: 1500
A27: =IF(D27>0,MAX($A$16:A26)+1,"") -> 3 | D27: Transporte 1 | G27: 600 | L27: 600 | P27: 600 | T27: 600
A28: =IF(D28>0,MAX($A$16:A27)+1,"")
A29: =IF(D29>0,MAX($A$16:A28)+1,"")
A30: =IF(D30>0,MAX($A$16:A29)+1,"")
A31: =IF(D31>0,MAX($A$16:A30)+1,"")
A33: =IF(D33>0,MAX($A$16:A32)+1,"")
A34: =IF(D34>0,MAX($A$16:A31)+1,"")
A35: =IF(D35>0,MAX($A$16:A32)+1,"") | C35: BR | E35: =_TAR2 -> 0
A36: =IF(D36>0,MAX($A$16:A34)+1,"") | C36: Actual | F36: =SUMIFS('Misselaneos '!$D:$D,'Misselaneos '!$B:$B,Balance!F1,'Misselaneos '!$E:$E,$C$35) -> 0 | G36: =SUMIFS('Misselaneos '!$D:$D,'Misselaneos '!$B:$B,Balance!G1,'Misselaneos '!$E:$E,$C$35) -> 0 | H36: =SUMIFS('Misselaneos '!$D:$D,'Misselaneos '!$B:$B,Balance!H1,'Misselaneos '!$E:$E,$C$35) -> 0 | I36: =SUMIFS('Misselaneos '!$D:$D,'Misselaneos '!$B:$B,Balance!I1,'Misselaneos '!$E:$E,$C$35) -> 0 | J36: =SUMIFS('Misselaneos '!$D:$D,'Misselaneos '!$B:$B,Balance!J1,'Misselaneos '!$E:$E,$C$35) -> 0 | K36: =SUMIFS('Misselaneos '!$D:$D,'Misselaneos '!$B:$B,Balance!K1,'Misselaneos '!$E:$E,$C$35) -> 0 | L36: =SUMIFS('Misselaneos '!$D:$D,'Misselaneos '!$B:$B,Balance!L1,'Misselaneos '!$E:$E,$C$35) -> 0 | M36: =SUMIFS('Misselaneos '!$D:$D,'Misselaneos '!$B:$B,Balance!M1,'Misselaneos '!$E:$E,$C$35) -> 0 | ... BJ36: =SUMIFS('Misselaneos '!$D:$D,'Misselaneos '!$B:$B,Balance!BJ1,'Misselaneos '!$E:$E,$C$35) -> 0
A37: =IF(D37>0,MAX($A$16:A35)+1,"")
A38: =IF(D38>0,MAX($A$16:A37)+1,"") -> 4 | D38: cell
A39: =IF(D39>0,MAX($A$16:A38)+1,"")
A41: =IF(D41>0,MAX($A$16:A39)+1,"")
A42: =IF(D42>0,MAX($A$16:A41)+1,"") | B42: Cuenta de Debito
A43: =IF(D43>0,MAX($A$16:A42)+1,"") | C43: Banco Popular | E43: =SUMIF(1:1,"<="&'Misselaneos '!H1,17:17)-SUMIF('Misselaneos '!E:E,Balance!C43,'Misselaneos '!D:D)+5119 -> 619 | F43: =SUM(F17:F20) -> 7000 | G43: =SUM(G17:G20) -> 7000 | H43: =SUM(H17:H20)-H44 -> 7000 | I43: =SUM(I17:I20)-I44 -> 7000 | J43: =SUM(J17:J20)-J44 -> 7000 | K43: =SUM(K17:K20)-K44 -> 7000 | L43: =SUM(L17:L20)-L44 -> 7000 | M43: =SUM(M17:M20)-M44 -> 7000 | N43: =SUM(N17:N20)-N44 -> 7000 | O43: =SUM(O17:O20)-O44 -> 7000 | P43: =SUM(P17:P20) -> 7000 | Q43: =SUM(Q17:Q20) -> 7000 | R43: =SUM(R17:R20) -> 7000 | S43: =SUM(S17:S20) -> 7000 | T43: =SUM(T17:T20) -> 7000 | U43: =SUM(U17:U20) -> 7000 | V43: =SUM(V17:V20) -> 0 | W43: =SUM(W17:W20) -> 0 | ... BJ43: =SUM(BJ17:BJ20) -> 7000
A44: =IF(D44>0,MAX($A$16:A43)+1,"") | C44: Actual | F44: =SUMIFS('Misselaneos '!$D:$D,'Misselaneos '!$B:$B,Balance!F1,'Misselaneos '!$E:$E,$C43) -> 0 | G44: =SUMIFS('Misselaneos '!$D:$D,'Misselaneos '!$B:$B,Balance!G1,'Misselaneos '!$E:$E,$C43) -> 0 | H44: =SUMIFS('Misselaneos '!$D:$D,'Misselaneos '!$B:$B,Balance!H1,'Misselaneos '!$E:$E,$C43) -> 0 | I44: =SUMIFS('Misselaneos '!$D:$D,'Misselaneos '!$B:$B,Balance!I1,'Misselaneos '!$E:$E,$C43) -> 0 | J44: =SUMIFS('Misselaneos '!$D:$D,'Misselaneos '!$B:$B,Balance!J1,'Misselaneos '!$E:$E,$C43) -> 0 | K44: =SUMIFS('Misselaneos '!$D:$D,'Misselaneos '!$B:$B,Balance!K1,'Misselaneos '!$E:$E,$C43) -> 0 | L44: =SUMIFS('Misselaneos '!$D:$D,'Misselaneos '!$B:$B,Balance!L1,'Misselaneos '!$E:$E,$C43) -> 0 | M44: =SUMIFS('Misselaneos '!$D:$D,'Misselaneos '!$B:$B,Balance!M1,'Misselaneos '!$E:$E,$C43) -> 0 | ... BJ44: =SUMIFS('Misselaneos '!$D:$D,'Misselaneos '!$B:$B,Balance!BJ1,'Misselaneos '!$E:$E,$C43) -> 0
A45: =IF(D45>0,MAX($A$16:A44)+1,"") -> 5 | D45: mantenimiento | G45: 2500
A46: =IF(D46>0,MAX($A$16:A45)+1,"") -> 6 | D46: renta | F46: 6000 | H46: 5000
A47: =IF(D47>0,MAX($A$16:A46)+1,"") -> 7 | D47: Salon | G47: 500
...

Sheet Misselaneos 
F1: =IF(H1=0,"",41824+(ROUNDUP(DAYS360(41824,H1)/7,0)*7)) -> 45821 | H1: =TODAY() -> 45877 | I1: Dias de | J1: Dia de | K1: Proximo | L1: Creditos | N1: Debitos | P1: Balance al
A2: Fecha | B2: We | C2: Concepto | D2: Monto | E2: Metodo de pago | H2: Cuentas | I2: Plazo | J2: Corta | K2: Corte | L2: Al Corte | M2: A la Fecha | N2: Al Corte | O2: A la Fecha | P2: Dif. Plan Vs. Act. | Q2: Fecha
A3: 43736 | B3: =IF(A3=0,"",41824+(ROUNDUP(DAYS360(41824,A3)/7,0)*7))+21+7 -> 43742 | C3: Luz | D3: 1000 | E3: Apap | H3: =Balance!C23 -> APAP | I3: 20 | J3: 1 | K3: =IF(DATE(YEAR($H$1),MONTH($H$1),J3)>$H$1,DATE(YEAR($H$1),MONTH($H$1),J3),DATE(YEAR($H$1),MONTH($H$1)+1,J3)) -> 45901 | L3: =SUMIF(Balance!$1:$1,"<="&K3+I3,Balance!$23:$23) -> 0 | M3: =SUMIF(Balance!$1:$1,"<="&H1,Balance!$23:$23) -> 0 | N3: =SUMIFS(D:D,A:A,"<="&K3,E:E,H3) -> 1000 | O3: =SUMIFS(D:D,A:A,"<="&$H$1,E:E,H3) -> 1000 | P3: =L3-N3 -> -1000 | Q3: =M3-O3 -> -1000 | S3: =365*44 -> 16060 | T3: =+Q3+S3 -> 15060
A4: 43739 | B4: =IF(A4=0,"",41824+(ROUNDUP(DAYS360(41824,A4)/7,0)*7))+21+7 -> 43742 | C4: Transporte | D4: 4500 | E4: Banco Popular | H4: =Balance!C35 -> BR | I4: 22 | J4: 15 | K4: =IF(DATE(YEAR($H$1),MONTH($H$1),J4)>$H$1,DATE(YEAR($H$1),MONTH($H$1),J4),DATE(YEAR($H$1),MONTH($H$1)+1,J4)) -> 45884 | L4: =SUMIF(Balance!$1:$1,"<="&K4+I4,Balance!$35:$35) -> 0 | M4: =SUMIF(Balance!$1:$1,"<="&H1,Balance!$35:$236) -> 0 | N4: =SUMIFS(D:D,A:A,"<="&K4,E:E,H4) -> 0 | O4: =SUMIFS(D:D,A:A,"<="&$H$1,E:E,H4) -> 0 | P4: =L4-N4 -> 0 | Q4: =M4-O4 -> 0
B5: =IF(A5=0,"",41824+(ROUNDUP(DAYS360(41824,A5)/7,0)*7))+21+7 -> #VALUE! | C5: renta | E5: Banco Popular | H5: =Balance!C43 -> Banco Popular | K5: =IF(DATE(YEAR($H$1),MONTH($H$1),J5)>$H$1,DATE(YEAR($H$1),MONTH($H$1),J5),DATE(YEAR($H$1),MONTH($H$1)+1,J5)) -> 45900 | P5: =L5-N5 -> 0 | Q5: =M5-O5 -> 0
E6: Banco Popular | H6: Cash
B7: =IF(A7=0,"",41824+(ROUNDUP(DAYS360(41824,A7)/7,0)*7))
B8: =IF(A8=0,"",41824+(ROUNDUP(DAYS360(41824,A8)/7,0)*7))
B9: =IF(A9=0,"",41824+(ROUNDUP(DAYS360(41824,A9)/7,0)*7))
B10: =IF(A10=0,"",41824+(ROUNDUP(DAYS360(41824,A10)/7,0)*7))
B11: =IF(A11=0,"",41824+(ROUNDUP(DAYS360(41824,A11)/7,0)*7))
B12: =IF(A12=0,"",41824+(ROUNDUP(DAYS360(41824,A12)/7,0)*7))
B13: =IF(A13=0,"",41824+(ROUNDUP(DAYS360(41824,A13)/7,0)*7))
B14: =IF(A14=0,"",41824+(ROUNDUP(DAYS360(41824,A14)/7,0)*7))
B15: =IF(A15=0,"",41824+(ROUNDUP(DAYS360(41824,A15)/7,0)*7))
B16: =IF(A16=0,"",41824+(ROUNDUP(DAYS360(41824,A16)/7,0)*7)) | H16: Gastos
B17: =IF(A17=0,"",41824+(ROUNDUP(DAYS360(41824,A17)/7,0)*7)) | G17: =G16+1 -> 1
B18: =IF(A18=0,"",41824+(ROUNDUP(DAYS360(41824,A18)/7,0)*7)) | G18: =G17+1 -> 2
B19: =IF(A19=0,"",41824+(ROUNDUP(DAYS360(41824,A19)/7,0)*7)) | G19: =G18+1 -> 3
B20: =IF(A20=0,"",41824+(ROUNDUP(DAYS360(41824,A20)/7,0)*7)) | G20: =G19+1 -> 4
B21: =IF(A21=0,"",41824+(ROUNDUP(DAYS360(41824,A21)/7,0)*7)) | G21: =G20+1 -> 5
B22: =IF(A22=0,"",41824+(ROUNDUP(DAYS360(41824,A22)/7,0)*7)) | G22: =G21+1 -> 6
B23: =IF(A23=0,"",41824+(ROUNDUP(DAYS360(41824,A23)/7,0)*7)) | G23: =G22+1 -> 7
B24: =IF(A24=0,"",41824+(ROUNDUP(DAYS360(41824,A24)/7,0)*7)) | G24: =G23+1 -> 8
B25: =IF(A25=0,"",41824+(ROUNDUP(DAYS360(41824,A25)/7,0)*7)) | G25: =G24+1 -> 9
B26: =IF(A26=0,"",41824+(ROUNDUP(DAYS360(41824,A26)/7,0)*7)) | G26: =G25+1 -> 10
B27: =IF(A27=0,"",41824+(ROUNDUP(DAYS360(41824,A27)/7,0)*7)) | G27: =G26+1 -> 11
B28: =IF(A28=0,"",41824+(ROUNDUP(DAYS360(41824,A28)/7,0)*7)) | G28: =G27+1 -> 12
... B42: =IF(A42=0,"",41824+(ROUNDUP(DAYS360(41824,A42)/7,0)*7)) | G42: =G41+1 -> 26
B43: =IF(A43=0,"",41824+(ROUNDUP(DAYS360(41824,A43)/7,0)*7)) | G43: =G42+1 -> 27 | H43: =IFERROR(VLOOKUP(G43,Balance!A:D,4,FALSE),"")
B44: =IF(A44=0,"",41824+(ROUNDUP(DAYS360(41824,A44)/7,0)*7)) | G44: =G43+1 -> 28
B45: =IF(A45=0,"",41824+(ROUNDUP(DAYS360(41824,A45)/7,0)*7)) | G45: =G44+1 -> 29
B46: =IF(A46=0,"",41824+(ROUNDUP(DAYS360(41824,A46)/7,0)*7)) | G46: =G45+1 -> 30
B47: =IF(A47=0,"",41824+(ROUNDUP(DAYS360(41824,A47)/7,0)*7)) | G47: =G46+1 -> 31
B48: =IF(A48=0,"",41824+(ROUNDUP(DAYS360(41824,A48)/7,0)*7)) | G48: =G47+1 -> 32
B49: =IF(A49=0,"",41824+(ROUNDUP(DAYS360(41824,A49)/7,0)*7)) | G49: =G48+1 -> 33
B50: =IF(A50=0,"",41824+(ROUNDUP(DAYS360(41824,A50)/7,0)*7)) | G50: =G49+1 -> 34
B51: =IF(A51=0,"",41824+(ROUNDUP(DAYS360(41824,A51)/7,0)*7)) | G51: =G50+1 -> 35
B52: =IF(A52=0,"",41824+(ROUNDUP(DAYS360(41824,A52)/7,0)*7)) | G52: =G51+1 -> 36
B53: =IF(A53=0,"",41824+(ROUNDUP(DAYS360(41824,A53)/7,0)*7)) | G53: =G52+1 -> 37
...

Sheet Eventos
A1: Mes | B1: Dia | C1: We | D1: Prox | E1: Eventos | F1: Presupuesto | G1: Actual
A2: 11 | B2: 20 | C2: =IF(D2=0,"",41642+(ROUNDUP(DAYS360(41642,D2)/7,0)*7))+21 -> 45940 | D2: =IF(A2=0,"",IF(TODAY()>DATE(YEAR(TODAY()),A2,B2),DATE(YEAR(TODAY())+1,A2,B2),DATE(YEAR(TODAY()),A2,B2))) -> 45981 | E2: dia de reyes | F2: 1000
A3: 2 | B3: 14 | C3: =IF(D3=0,"",41642+(ROUNDUP(DAYS360(41642,D3)/7,0)*7))+21 -> 46024 | D3: =IF(A3=0,"",IF(TODAY()>DATE(YEAR(TODAY()),A3,B3),DATE(YEAR(TODAY())+1,A3,B3),DATE(YEAR(TODAY()),A3,B3))) -> 46067 | E3: dia de la amistad | F3: 2000
A4: 10 | B4: 15 | C4: =IF(D4=0,"",41642+(ROUNDUP(DAYS360(41642,D4)/7,0)*7))+21 -> 45905 | D4: =IF(A4=0,"",IF(TODAY()>DATE(YEAR(TODAY()),A4,B4),DATE(YEAR(TODAY())+1,A4,B4),DATE(YEAR(TODAY()),A4,B4))) -> 45945 | E4: semana santa | F4: 10000
A5: 9 | B5: 5 | C5: =IF(D5=0,"",41642+(ROUNDUP(DAYS360(41642,D5)/7,0)*7))+21 -> 45870 | D5: =IF(A5=0,"",IF(TODAY()>DATE(YEAR(TODAY()),A5,B5),DATE(YEAR(TODAY())+1,A5,B5),DATE(YEAR(TODAY()),A5,B5))) -> 45905 | E5: cumple de pedro | F5: 1500
D6: =IF(A6=0,"",IF(TODAY()>DATE(YEAR(TODAY()),A6,B6),DATE(YEAR(TODAY())+1,A6,B6),DATE(YEAR(TODAY()),A6,B6)))
D7: =IF(A7=0,"",IF(TODAY()>DATE(YEAR(TODAY()),A7,B7),DATE(YEAR(TODAY())+1,A7,B7),DATE(YEAR(TODAY()),A7,B7)))
D8: =IF(A8=0,"",IF(TODAY()>DATE(YEAR(TODAY()),A8,B8),DATE(YEAR(TODAY())+1,A8,B8),DATE(YEAR(TODAY()),A8,B8)))
D9: =IF(A9=0,"",IF(TODAY()>DATE(YEAR(TODAY()),A9,B9),DATE(YEAR(TODAY())+1,A9,B9),DATE(YEAR(TODAY()),A9,B9)))
D10: =IF(A10=0,"",IF(TODAY()>DATE(YEAR(TODAY()),A10,B10),DATE(YEAR(TODAY())+1,A10,B10),DATE(YEAR(TODAY()),A10,B10)))
D11: =IF(A11=0,"",IF(TODAY()>DATE(YEAR(TODAY()),A11,B11),DATE(YEAR(TODAY())+1,A11,B11),DATE(YEAR(TODAY()),A11,B11)))
D12: =IF(A12=0,"",IF(TODAY()>DATE(YEAR(TODAY()),A12,B12),DATE(YEAR(TODAY())+1,A12,B12),DATE(YEAR(TODAY()),A12,B12)))
D13: =IF(A13=0,"",IF(TODAY()>DATE(YEAR(TODAY()),A13,B13),DATE(YEAR(TODAY())+1,A13,B13),DATE(YEAR(TODAY()),A13,B13)))
D14: =IF(A14=0,"",IF(TODAY()>DATE(YEAR(TODAY()),A14,B14),DATE(YEAR(TODAY())+1,A14,B14),DATE(YEAR(TODAY()),A14,B14)))
D15: =IF(A15=0,"",IF(TODAY()>DATE(YEAR(TODAY()),A15,B15),DATE(YEAR(TODAY())+1,A15,B15),DATE(YEAR(TODAY()),A15,B15)))
D16: =IF(A16=0,"",IF(TODAY()>DATE(YEAR(TODAY()),A16,B16),DATE(YEAR(TODAY())+1,A16,B16),DATE(YEAR(TODAY()),A16,B16)))
D17: =IF(A17=0,"",IF(TODAY()>DATE(YEAR(TODAY()),A17,B17),DATE(YEAR(TODAY())+1,A17,B17),DATE(YEAR(TODAY()),A17,B17)))
... D31: =IF(A31=0,"",IF(TODAY()>DATE(YEAR(TODAY()),A31,B31),DATE(YEAR(TODAY())+1,A31,B31),DATE(YEAR(TODAY()),A31,B31)))
D32: =IF(C32=0,"",41642+(ROUNDUP(DAYS360(41642,C32)/7,0)*7))
D33: =IF(C33=0,"",41642+(ROUNDUP(DAYS360(41642,C33)/7,0)*7))
D34: =IF(C34=0,"",41642+(ROUNDUP(DAYS360(41642,C34)/7,0)*7))
D35: =IF(C35=0,"",41642+(ROUNDUP(DAYS360(41642,C35)/7,0)*7))
D36: =IF(C36=0,"",41642+(ROUNDUP(DAYS360(41642,C36)/7,0)*7))
D37: =IF(C37=0,"",41642+(ROUNDUP(DAYS360(41642,C37)/7,0)*7))
D38: =IF(C38=0,"",41642+(ROUNDUP(DAYS360(41642,C38)/7,0)*7))
D39: =IF(C39=0,"",41642+(ROUNDUP(DAYS360(41642,C39)/7,0)*7))
D40: =IF(C40=0,"",41642+(ROUNDUP(DAYS360(41642,C40)/7,0)*7))
D41: =IF(C41=0,"",41642+(ROUNDUP(DAYS360(41642,C41)/7,0)*7))
D42: =IF(C42=0,"",41642+(ROUNDUP(DAYS360(41642,C42)/7,0)*7))
D43: =IF(C43=0,"",41642+(ROUNDUP(DAYS360(41642,C43)/7,0)*7))
... D58: =IF(C58=0,"",41642+(ROUNDUP(DAYS360(41642,C58)/7,0)*7))

Sheet Sheet2
J2: APAP | K2: 1
J3: BR | K3: 15
C5: Concepto | D5: fecha de compromiso | E5: Monto | F5: Metodo de pago
C6: luz | D6: 5 | E6: 1500 | F6: apap | H6: =+E6*1.2 -> 1800
C7: mantenimiento | D7: 30 | E7: 2500 | F7: banco popular
C8: renta | D8: 25 | E8: 10000 | F8: banco popular
C9: cell | D9: 16 | E9: 2000 | F9: BR | H9: =+E9*1.2 -> 2400
C10: Salon | D10: 1 | E10: 500 | F10: banco popular
C11: Salon | D11: 7 | E11: 500 | F11: banco popular
C12: Salon | D12: 14 | E12: 500 | F12: banco popular
C13: Salon | D13: 21 | E13: 500 | F13: banco popular
C14: Transporte 1 | E14: 600 | F14: apap
C15: Transporte 2 | E15: 600 | F15: BR
C16: Transporte 3 | E16: 600 | F16: banco popular
C17: Transporte 4 | E17: 600 | F17: banco popular
E19: =SUBTOTAL(9,E6:E18) -> 15700
E20: =+E19*1.15 -> 18055
